Traceback (most recent call last):
  File "/Users/benjaminwinjum/Library/CloudStorage/Box-Box/jupyterbooks/jbook1/lib/python3.9/site-packages/jupyter_cache/executors/utils.py", line 51, in single_nb_execution
    executenb(
  File "/Users/benjaminwinjum/Library/CloudStorage/Box-Box/jupyterbooks/jbook1/lib/python3.9/site-packages/nbclient/client.py", line 1204, in execute
    return NotebookClient(nb=nb, resources=resources, km=km, **kwargs).execute()
  File "/Users/benjaminwinjum/Library/CloudStorage/Box-Box/jupyterbooks/jbook1/lib/python3.9/site-packages/nbclient/util.py", line 84, in wrapped
    return just_run(coro(*args, **kwargs))
  File "/Users/benjaminwinjum/Library/CloudStorage/Box-Box/jupyterbooks/jbook1/lib/python3.9/site-packages/nbclient/util.py", line 62, in just_run
    return loop.run_until_complete(coro)
  File "/usr/local/Cellar/python@3.9/3.9.5/Frameworks/Python.framework/Versions/3.9/lib/python3.9/asyncio/base_events.py", line 642, in run_until_complete
    return future.result()
  File "/Users/benjaminwinjum/Library/CloudStorage/Box-Box/jupyterbooks/jbook1/lib/python3.9/site-packages/nbclient/client.py", line 663, in async_execute
    await self.async_execute_cell(
  File "/Users/benjaminwinjum/Library/CloudStorage/Box-Box/jupyterbooks/jbook1/lib/python3.9/site-packages/nbclient/client.py", line 965, in async_execute_cell
    await self._check_raise_for_error(cell, cell_index, exec_reply)
  File "/Users/benjaminwinjum/Library/CloudStorage/Box-Box/jupyterbooks/jbook1/lib/python3.9/site-packages/nbclient/client.py", line 862, in _check_raise_for_error
    raise CellExecutionError.from_cell_and_msg(cell, exec_reply_content)
nbclient.exceptions.CellExecutionError: An error occurred while executing the following cell:
------------------
import plotly.express as px

fig = px.scatter_mapbox(green,
                        lat=green.geometry.y,
                        lon=green.geometry.x,
                        hover_name="Type",
                        hover_data=['Type','Name','Street Address'],
                        color="Type",
                        zoom=10,
                        height=600,
                       mapbox_style='stamen-toner')
fig.update_traces(marker={'size': 15})
fig.show()
------------------

[0;31m---------------------------------------------------------------------------[0m
[0;31mModuleNotFoundError[0m                       Traceback (most recent call last)
Input [0;32mIn [30][0m, in [0;36m<cell line: 1>[0;34m()[0m
[0;32m----> 1[0m [38;5;28;01mimport[39;00m [38;5;21;01mplotly[39;00m[38;5;21;01m.[39;00m[38;5;21;01mexpress[39;00m [38;5;28;01mas[39;00m [38;5;21;01mpx[39;00m
[1;32m      3[0m fig [38;5;241m=[39m px[38;5;241m.[39mscatter_mapbox(green,
[1;32m      4[0m                         lat[38;5;241m=[39mgreen[38;5;241m.[39mgeometry[38;5;241m.[39my,
[1;32m      5[0m                         lon[38;5;241m=[39mgreen[38;5;241m.[39mgeometry[38;5;241m.[39mx,
[0;32m   (...)[0m
[1;32m     10[0m                         height[38;5;241m=[39m[38;5;241m600[39m,
[1;32m     11[0m                        mapbox_style[38;5;241m=[39m[38;5;124m'[39m[38;5;124mstamen-toner[39m[38;5;124m'[39m)
[1;32m     12[0m fig[38;5;241m.[39mupdate_traces(marker[38;5;241m=[39m{[38;5;124m'[39m[38;5;124msize[39m[38;5;124m'[39m: [38;5;241m15[39m})

[0;31mModuleNotFoundError[0m: No module named 'plotly'
ModuleNotFoundError: No module named 'plotly'

